Óúè ÓØá .venv  üêç  v3.13.0 Admin in linduarte.github.io (Ôêò main) ‚úó
pytest -q -s tests/test_04_auth_flow_e2e.py::test_complete_login_flow -q -s
F
=========================================== FAILURES ============================================
______________________________ test_complete_login_flow[chromium] _______________________________
tests\test_04_auth_flow_e2e.py:83: in test_complete_login_flow
    expect(success_locator).to_be_visible(timeout=5000)
E   AssertionError: Locator expected to be visible
E   Actual value: <element(s) not found>
E   Call log:
E     - Expect "to_be_visible" with timeout 5000ms
E     - waiting for get_by_text(re.compile(r"sucesso|ok|success", re.IGNORECASE))

During handling of the above exception, another exception occurred:
tests\test_04_auth_flow_e2e.py:90: in test_complete_login_flow
    raise AssertionError(f"Erro no teste de login: {e}")
E   AssertionError: Erro no teste de login: Locator expected to be visible
E   Actual value: <element(s) not found>
E   Call log:
E     - Expect "to_be_visible" with timeout 5000ms
E     - waiting for get_by_text(re.compile(r"sucesso|ok|success", re.IGNORECASE))
==================================== short test summary info ====================================
FAILED tests/test_04_auth_flow_e2e.py::test_complete_login_flow[chromium] - AssertionError: Erro no teste de login: Locator expected to be visible
